Workbook
Name \A: [1]SSA!#REF!
Name \c: #REF!
Name \S: [1]SSA!#REF!
Name _ACT1: #REF!
Name _ACT2: #REF!
Name _ADJ1: #REF!
Name _ADJ2: #REF!
Name _bc2: #REF!
Name _e1: #REF!
Name _K1: #REF!
Name _k2: #REF!
Name _K4: #REF!
Name _LD1: #N/A
Name _LD2: #N/A
Name _LP2: #REF!
Name _mxz1: #REF!
Name _mxz11: #REF!
Name _MXZ9: #REF!
Name _o2: #REF!
Name _PG2: #N/A
Name _pnl96: #REF!
Name _TV2: #REF!
Name a: #REF!
Name A_DescriptionList: '[2]Interim --> Top'!$E$3:$E$111
Name aaaaaaaaaaaa: '[3]tax-ss'!$B$51
Name AAClaim: #REF!
Name ae: #REF!
Name ALLOT1: #REF!
Name ALLOT2: #REF!
Name ans: #REF!
Name Answer_D2: #REF!
Name Answer_D2.1: #REF!
Name Answer_E2: #REF!
Name Answer_E2_Range2: #REF!
Name Answer_F2: #REF!
Name Answer_F2_Range2: #REF!
Name Answer_F2_Range3: #REF!
Name Answer_G2: #REF!
Name Answer_H2: #REF!
Name Answer_H2_Range2: #REF!
Name Answer_I2: #REF!
Name Answer_I2_Range2: #REF!
Name Answer_I2_Range3: #REF!
Name Answer_I2_Range4: #REF!
Name Answer_J2: #REF!
Name Answer_J2_Range2: #REF!
Name Answer_J2_Range3: #REF!
Name Answer_J2_Range4: #REF!
Name Answer_K2: #REF!
Name Answer_K2_Range2: #REF!
Name Answer_L2: #REF!
Name Answer_L2_Range2: #REF!
Name Answer_L2_Range3: #REF!
Name Answer_L2_Range4: #REF!
Name Answer_M2: #REF!
Name Answer_N2: #REF!
Name Answer_O2: #REF!
Name Answer_O2_Range2: #REF!
Name Answer_O2_Range3: #REF!
Name Answer_P2: #REF!

Sheet 收入相关
A1: 细节测试
A2: No. | B2: Customer name | C2: amount | D2: Voucher date | E2: Confirmation Letter amount | F2: Confirmation Letter Date | G2: Invoice no. | H2: Invoice date | I2: Currency
A3: 164 | B3: 360 Movement LLC | C3: 4000 | D3: 20250307 | I3: USDT
A4: 69 | B4: 404 BLOCKCHAIN LLC | C4: 9000 | D4: 20241206 | I4: USDT
A5: 136 | B5: 404 BLOCKCHAIN LLC | C5: 25000 | D5: 20250210 | I5: USDT
A6: 95 | B6: ABSOLUTE BLOCKCHAIN INC. | C6: 2000 | D6: 20250102 | I6: USDT
A7: 109 | B7: ACME HYPERION LTD | C7: 22500 | D7: 20250115 | I7: USDT
A8: 7 | B8: AI CRYPTO QUANT STRATEGIES PTE. LTD. | C8: 13333.33 | D8: 20241010 | I8: USDT
A9: 38 | B9: ALL IN CRYPTO LLC | C9: 100 | D9: 20241114 | I9: USDT
A10: 43 | B10: ALL IN CRYPTO LLC | C10: 14000 | D10: 20241118 | I10: USDT
A11: 63 | B11: ALL IN CRYPTO LLC | C11: 4000 | D11: 20241203 | I11: USDT
A12: 76 | B12: ALPACA CRYPTO LLC | C12: 1949 | D12: 20241213 | I12: USDT
A13: 78 | B13: AMINA (SINGAPORE) PTE. LTD. | C13: 3518.52 | D13: 20241217 | I13: USDT
A14: 141 | B14: AMINA (SINGAPORE) PTE. LTD. | C14: 18165.14 | D14: 20250212 | I14: USDT
... A211: 96 | B211: Yuzu INC. | C211: 3600 | D211: 20240326 | I211: USDT
A215: 截止测试
A216: No. | B216: Name of customer | C216: Voucher date | D216: Voucher number | G216: Invoice number | H216: Invoice date | I216: Currency
E218: Confirmation Letter amount | F218: Confirmation Letter Date
A219: 2 | B219: XMONEY PTY LTD | C219: 20250907 | D219: 49 | I219: USDT
A220: 3 | B220: XMONEY PTY LTD | C220: 20250915 | D220: 60 | I220: USDT
A221: 12 | B221: WEB3 LABS LTD | C221: 20240911 | D221: 40 | I221: USDT
A222: 20 | B222: WEB3 LABS LTD | C222: 20240920 | D222: 75 | I222: USDT
A223: 4 | B223: WEB3 ENGINEERING LTD | C223: 20250915 | D223: 59 | I223: USDT
A224: 17 | B224: UNTITLED CORPORATION PROJECT INC. | C224: 20240916 | D224: 68 | I224: USDT
A225: 13 | B225: TRADERS.TECH LIMITED | C225: 20240912 | D225: 43 | I225: USDT
A226: 18 | B226: The Payment Solution Limited | C226: 20240918 | D226: 71 | I226: USDT
A227: 27 | B227: STREAMFLOW CYPRUS LTD | C227: 20240926 | D227: 92 | I227: USDT
A228: 10 | B228: Soda Ventures LTD | C228: 20250927 | D228: 85 | I228: USDT
A229: 1 | B229: Router Works, Inc. | C229: 20240902 | D229: 2 | I229: USDT
A230: 23 | B230: Router Works, Inc. | C230: 20240924 | D230: 81 | I230: USDT
... A268: 4 | B268: 404 BLOCKCHAIN LLC | C268: 20240904 | D268: 9 | I268: USDT
A269: 1 | B269: TROPIC SEASCAPE PTE. LTD | C269: 20251015 | D269: 37 | I269: USDT
A270: 2 | B270: Mercury Protocol PTE. LTD | C270: 20251001 | D270: 26 | I270: USDT
A271: 3 | B271: Orion Limited | C271: 20251014 | D271: 69 | I271: USDT
A272: 4 | B272: RARESHOP LIMITED | C272: 20251008 | D272: 43 | I272: USDT
A273: 5 | B273: Superchillclub Limited | C273: 20251025 | D273: 44 | I273: USDT
A274: 6 | B274: Rivera Money Inc | C274: 20251017 | D274: 34 | I274: USDT
A275: 7 | B275: RARESHOP LIMITED | C275: 20251010 | D275: 32 | I275: USDT
A276: 8 | B276: Echo International Group Corp | C276: 20251016 | D276: 23 | I276: USDT
A277: 9 | B277: Gumi Inc | C277: 20251021 | D277: 24 | I277: USDT
...

Sheet Sheet1
A1: No | B1: Date | C1: Voucher number | D1: Abstract | E1: USD | F1: Account Name | G1: Abstract | H1: 成本 | I1: Project Name | J1: Payer Name | K1: To
A2: 1 | B2: 2024-12-05 | C2: 10 | D2: 21335372 | E2: 1850 | F2: Promotion expenses | G2: 21335372 | H2: Sales expenses - Promotion fees | I2: {=_xlfn.XLOOKUP(TEXT(G2,"0"),TEXT(数据!$A:$A,"0"),数据!$B:$B,"")} -> 英文媒体 | J2: Web3 News Wire | K2: {=_xlfn.XLOOKUP(TEXT(G2,"0"),TEXT(数据!$A:$A,"0"),数据!$D:$D,"")} -> 0x9aab5dc375666352404ea30c4be9b75b527bdd12
A3: 2 | B3: 2024-12-10 | C3: 30 | D3: 44724294 | E3: 2940 | F3: Promotion expenses | G3: 44724294 | H3: Sales expenses - Promotion fees | I3: {=_xlfn.XLOOKUP(TEXT(G3,"0"),TEXT(数据!$A:$A,"0"),数据!$B:$B,"")} -> Seapad 渠道 | J3: A&A BLOCKCHAIN TECHNOLOGY INNOVATION PTE. LTD. | K3: {=_xlfn.XLOOKUP(TEXT(G3,"0"),TEXT(数据!$A:$A,"0"),数据!$D:$D,"")} -> 0xf7c0aede609dd5e13a1d34900a172a1566264fbe
A4: 4 | B4: 2024-12-10 | C4: 32 | D4: 44724274 | E4: 2200 | F4: Promotion expenses | G4: 44724274 | H4: Sales expenses - Promotion fees | I4: {=_xlfn.XLOOKUP(TEXT(G4,"0"),TEXT(数据!$A:$A,"0"),数据!$B:$B,"")} -> Alex - Nemo 渠道 | J4: A&A BLOCKCHAIN TECHNOLOGY INNOVATION PTE. LTD. | K4: {=_xlfn.XLOOKUP(TEXT(G4,"0"),TEXT(数据!$A:$A,"0"),数据!$D:$D,"")} -> 0x0f53e8377072dab07876d24a00b8f440f2bb49d9
A5: 6 | B5: 2024-12-10 | C5: 36 | D5: 44724252 | E5: 19600 | F5: Promotion expenses | G5: 44724252 | H5: Sales expenses - Promotion fees | I5: {=_xlfn.XLOOKUP(TEXT(G5,"0"),TEXT(数据!$A:$A,"0"),数据!$B:$B,"")} -> Bitslab支出给越南henry，合作Commission | J5: Henry | K5: {=_xlfn.XLOOKUP(TEXT(G5,"0"),TEXT(数据!$A:$A,"0"),数据!$D:$D,"")} -> 0x60f6a549b234a2f9a0c050f26acc43ea7c73b0af
A6: 7 | B6: 2024-12-25 | C6: 78 | D6: 21477477 | E6: 1450 | F6: Promotion expenses | G6: 21477477 | H6: Sales expenses - Promotion fees | I6: {=_xlfn.XLOOKUP(TEXT(G6,"0"),TEXT(数据!$A:$A,"0"),数据!$B:$B,"")} -> 英文媒体传播费用 | J6: Web3 News Wire | K6: {=_xlfn.XLOOKUP(TEXT(G6,"0"),TEXT(数据!$A:$A,"0"),数据!$D:$D,"")} -> 0x9aab5dc375666352404ea30c4be9b75b527bdd12
A7: 13 | B7: 2025-01-05 | C7: 15 | D7: 292124417 | E7: 2160 | F7: Promotion expenses | G7: 292124417 | H7: Sales expenses - Promotion fees | I7: {=_xlfn.XLOOKUP(TEXT(G7,"0"),TEXT(数据!$A:$A,"0"),数据!$B:$B,"")} -> 卢毅渠道 | J7: BXWEB3 TECHNOLOGY LIMITED | K7: {=_xlfn.XLOOKUP(TEXT(G7,"0"),TEXT(数据!$A:$A,"0"),数据!$D:$D,"")} -> 0xba3e38429ba3f113935a3b728844620eb7569406
A8: 18 | B8: 2025-04-25 | C8: 59 | D8: 22339398 | E8: 2200 | F8: Promotion expenses | G8: 22339398 | H8: Sales expenses - Promotion fees | I8: {=_xlfn.XLOOKUP(TEXT(G8,"0"),TEXT(数据!$A:$A,"0"),数据!$B:$B,"")} -> 媒体费用 | J8: Web3 News Wire | K8: {=_xlfn.XLOOKUP(TEXT(G8,"0"),TEXT(数据!$A:$A,"0"),数据!$D:$D,"")} -> 0x9aab5dc375666352404ea30c4be9b75b527bdd12
A9: 21 | B9: 2025-05-18 | C9: 46 | D9: 22507240 | E9: 1650 | F9: Promotion expenses | G9: 22507240 | H9: Sales expenses - Promotion fees | I9: {=_xlfn.XLOOKUP(TEXT(G9,"0"),TEXT(数据!$A:$A,"0"),数据!$B:$B,"")} -> Decrept漏洞传播媒体费用 | J9: Decrept | K9: {=_xlfn.XLOOKUP(TEXT(G9,"0"),TEXT(数据!$A:$A,"0"),数据!$D:$D,"")} -> 0x9aab5dc375666352404ea30c4be9b75b527bdd12
A10: 22 | B10: 2025-08-06 | C10: 11 | D10: 23078858 | E10: 1500 | F10: Promotion expenses | G10: 23078858 | H10: Sales expenses - Promotion fees | I10: {=_xlfn.XLOOKUP(TEXT(G10,"0"),TEXT(数据!$A:$A,"0"),数据!$B:$B,"")} -> CPChain 渠道 | J10: BXWEB3 TECHNOLOGY LIMITED | K10: {=_xlfn.XLOOKUP(TEXT(G10,"0"),TEXT(数据!$A:$A,"0"),数据!$D:$D,"")} -> 0x48d6c1f62d50b73332cb59d1116c93a0efec95a1
A11: 23 | B11: 2025-08-06 | C11: 12 | D11: 23078846 | E11: 2295 | F11: Promotion expenses | G11: 23078846 | H11: Sales expenses - Promotion fees | I11: {=_xlfn.XLOOKUP(TEXT(G11,"0"),TEXT(数据!$A:$A,"0"),数据!$B:$B,"")} -> Avalon 渠道 | J11: BXWEB3 TECHNOLOGY LIMITED | K11: {=_xlfn.XLOOKUP(TEXT(G11,"0"),TEXT(数据!$A:$A,"0"),数据!$D:$D,"")} -> 0xaee6f674d112ca8ec62496611cdb87a562279e86
A12: 24 | B12: 2025-09-04 | C12: 25 | D12: 59983249 | E12: 2817 | F12: Promotion expenses | G12: 59983249 | H12: Sales expenses - Promotion fees | I12: {=_xlfn.XLOOKUP(TEXT(G12,"0"),TEXT(数据!$A:$A,"0"),数据!$B:$B,"")} -> DUNSHEA LUKE ANDREW ALLAN / Senior Security Auditor | J12: DUNSHEA LUKE ANDREW ALLAN | K12: {=_xlfn.XLOOKUP(TEXT(G12,"0"),TEXT(数据!$A:$A,"0"),数据!$D:$D,"")} -> 0x62ce31584c85497D986aDBbFff23c890daDF5EF1
A13: 25 | B13: 2025-09-18 | C13: 66 | D13: 61567559 | E13: 1716 | F13: Promotion expenses | G13: 61567559 | H13: Sales expenses - Promotion fees | I13: {=_xlfn.XLOOKUP(TEXT(G13,"0"),TEXT(数据!$A:$A,"0"),数据!$B:$B,"")} -> imentus 渠道 | J13: imentus | K13: {=_xlfn.XLOOKUP(TEXT(G13,"0"),TEXT(数据!$A:$A,"0"),数据!$D:$D,"")} -> 0x2aEA62c4F8b335Cef380416238B59eab2eA01c73
A14: 26 | B14: 2025-09-18 | C14: 67 | D14: 61567809 | E14: 5000 | F14: Promotion expenses | G14: 61567809 | H14: Sales expenses - Promotion fees | I14: {=_xlfn.XLOOKUP(TEXT(G14,"0"),TEXT(数据!$A:$A,"0"),数据!$B:$B,"")} -> Plug&Play的Max | J14: Plug&Play | K14: {=_xlfn.XLOOKUP(TEXT(G14,"0"),TEXT(数据!$A:$A,"0"),数据!$D:$D,"")} -> 0x49cFd9ee1382d043f0C3a85a42905cd4e73D6AB7
A15: 27 | B15: 2025-09-18 | C15: 68 | D15: 61567930 | E15: 4000 | F15: Promotion expenses | G15: 61567930 | H15: Sales expenses - Promotion fees | I15: {=_xlfn.XLOOKUP(TEXT(G15,"0"),TEXT(数据!$A:$A,"0"),数据!$B:$B,"")} -> junhao 顾问费 | J15: junhao | K15: {=_xlfn.XLOOKUP(TEXT(G15,"0"),TEXT(数据!$A:$A,"0"),数据!$D:$D,"")} -> 0xfB57339369e0D88f5D469CA7079d501e8E813a68
A16: 28 | B16: 2024-11-12 | C16: 59 | D16: 21165630 | E16: 9500 | F16: Audit fee | G16: 21165630 | H16: Administrative Expenses - Office Expenses | I16: {=_xlfn.XLOOKUP(TEXT(G16,"0"),TEXT(数据!$A:$A,"0"),数据!$B:$B,"")} -> 公司三个主体的年审 | J16: AVAILABIZ PTE LTD | K16: {=_xlfn.XLOOKUP(TEXT(G16,"0"),TEXT(数据!$A:$A,"0"),数据!$D:$D,"")} -> 0x2621c6c3f585463020cf8fa1e3c92f7031ad1181
A17: 29 | B17: 2025-04-08 | C17: 19 | D17: 323891119 | E17: 2000 | F17: Audit fee | G17: 323891119 | H17: Administrative Expenses - Office Expenses | I17: {=_xlfn.XLOOKUP(TEXT(G17,"0"),TEXT(数据!$A:$A,"0"),数据!$B:$B,"")} -> ret2basic.eth | J17: ret2basic | K17: {=_xlfn.XLOOKUP(TEXT(G17,"0"),TEXT(数据!$A:$A,"0"),数据!$D:$D,"")} -> 0x75a24dc4efc5324f2253abacb98a296ac49448ca
A18: 30 | B18: 2024-10-25 | C18: 71 | D18: 43417628 | E18: 12780 | F18: Other event expenses | G18: 43417628 | H18: Sales Expense - Event | I18: {=_xlfn.XLOOKUP(TEXT(G18,"0"),TEXT(数据!$A:$A,"0"),数据!$B:$B,"")} -> Movement Afterparty at Thailand | J18: Movement | K18: {=_xlfn.XLOOKUP(TEXT(G18,"0"),TEXT(数据!$A:$A,"0"),数据!$D:$D,"")} -> 0x70b7566282f321229468e4809c30efcae65a8bfa
A19: 31 | B19: 2024-11-04 | C19: 66 | D19: 21113385 | E19: 10000 | F19: Other event expenses | G19: 21113385 | H19: Sales Expense - Event | I19: {=_xlfn.XLOOKUP(TEXT(G19,"0"),TEXT(数据!$A:$A,"0"),数据!$B:$B,"")} -> Movement | J19: Winny | K19: {=_xlfn.XLOOKUP(TEXT(G19,"0"),TEXT(数据!$A:$A,"0"),数据!$D:$D,"")} -> 0xb0599d3eb50ba5b17b520875d4d25af528f0bfd1
A20: 32 | B20: 2025-02-15 | C20: 62 | D20: 21845084 | E20: 22883 | F20: Other event expenses | G20: 21845084 | H20: Sales Expense - Event | I20: {=_xlfn.XLOOKUP(TEXT(G20,"0"),TEXT(数据!$A:$A,"0"),数据!$B:$B,"")} -> TONX黑客松费用 | J20: TONX | K20: {=_xlfn.XLOOKUP(TEXT(G20,"0"),TEXT(数据!$A:$A,"0"),数据!$D:$D,"")} -> 0x14b0fdab8c8fe4314dad4eb8fb019635e3f99e09
A21: 33 | B21: 2025-03-07 | C21: 16 | D21: 21993365 | E21: -7295 | F21: Other event expenses | G21: 21993365 | H21: Sales Expense - Event | I21: {=_xlfn.XLOOKUP(TEXT(G21,"0"),TEXT(数据!$A:$A,"0"),数据!$B:$B,"")} -> TONX黑客松费用（結算） | J21: AI CRYPTO QUANT STRATEGIES PTE. LTD. | K21: {=_xlfn.XLOOKUP(TEXT(G21,"0"),TEXT(数据!$A:$A,"0"),数据!$D:$D,"")} -> 0x5e75effbb5147e0840d0b7e2052ec3c04119f49f
A22: 38 | B22: 2024-02-09 | C22: 35 | D22: 35970263 | E22: 5000 | F22: Brand promotion expenses | G22: 35970263 | H22: Sales expenses - Brand promotion expenses | I22: {=_xlfn.XLOOKUP(TEXT(G22,"0"),TEXT(数据!$A:$A,"0"),数据!$B:$B,"")} -> ZKCTF 第一名 | J22: ZKCTF | K22: {=_xlfn.XLOOKUP(TEXT(G22,"0"),TEXT(数据!$A:$A,"0"),数据!$D:$D,"")} -> 0xe1697cf0b5f90420379a1c98f3ccb9f6fbfe119b
A23: 40 | B23: 2024-08-29 | C23: 71 | D23: 20632877 | E23: 10000 | F23: Brand promotion expenses | G23: 20632877 | H23: Sales expenses - Brand promotion expenses | I23: {=_xlfn.XLOOKUP(TEXT(G23,"0"),TEXT(数据!$A:$A,"0"),数据!$B:$B,"")} -> 9.19 TON 活动赞助费用 | J23: TONX | K23: {=_xlfn.XLOOKUP(TEXT(G23,"0"),TEXT(数据!$A:$A,"0"),数据!$D:$D,"")} -> 0x2adcea82d699f3e20312daadd60ce9dd0616d77c
A24: 41 | B24: 2024-09-02 | C24: 3 | D24: 249149323 | E24: 2502 | F24: Brand promotion expenses | G24: 249149323 | H24: Sales expenses - Brand promotion expenses | I24: {=_xlfn.XLOOKUP(TEXT(G24,"0"),TEXT(数据!$A:$A,"0"),数据!$B:$B,"")} -> TON CTF 奖金池 | J24: TON CTF | K24: {=_xlfn.XLOOKUP(TEXT(G24,"0"),TEXT(数据!$A:$A,"0"),数据!$D:$D,"")} -> 0xdc9c27203edf644cac8f0e53fab810977f7a3361
A25: 42 | B25: 2023-11-03 | C25: 1 | D25: 18489905 | E25: 5225 | F25: Office expenses | G25: 18489905 | H25: Administrative expenses - office expenses | I25: {=_xlfn.XLOOKUP(TEXT(G25,"0"),TEXT(数据!$A:$A,"0"),数据!$B:$B,"")} -> 新加坡公司注册费用 | J25: AVAILABIZ PTE LTD | K25: {=_xlfn.XLOOKUP(TEXT(G25,"0"),TEXT(数据!$A:$A,"0"),数据!$D:$D,"")} -> 0x6bde7a4bc4cfc75429f65b90227496d3cad6424c
A26: 43 | B26: 2024-04-16 | C26: 48 | D26: 19660796 | E26: 8470 | F26: Office expenses | G26: 19660796 | H26: Administrative expenses - office expenses | I26: {=_xlfn.XLOOKUP(TEXT(G26,"0"),TEXT(数据!$A:$A,"0"),数据!$B:$B,"")} -> poppy 离案公司注册和变更 | J26: AVAILABIZ PTE LTD | K26: {=_xlfn.XLOOKUP(TEXT(G26,"0"),TEXT(数据!$A:$A,"0"),数据!$D:$D,"")} -> 0x6bde7a4bc4cfc75429f65b90227496d3cad6424c
A27: 44 | B27: 2024-02-26 | C27: 61 | D27: 19310019 | E27: 1398.91 | F27: Exhibition expenses | G27: 19310019 | H27: Sales Expense - Exhibition | I27: {=_xlfn.XLOOKUP(TEXT(G27,"0"),TEXT(数据!$A:$A,"0"),数据!$B:$B,"")} -> btc l2 大会英文 pr费用 | J27: web3 news wire | K27: {=_xlfn.XLOOKUP(TEXT(G27,"0"),TEXT(数据!$A:$A,"0"),数据!$D:$D,"")} -> 0x5583c8cf2921f69f09ec7a3663dce255a26e11e4
A28: 46 | B28: 2024-04-30 | C28: 109 | D28: 206346955 | E28: 5435 | F28: Exhibition expenses | G28: 206346955 | H28: Sales Expense - Exhibition | I28: {=_xlfn.XLOOKUP(TEXT(G28,"0"),TEXT(数据!$A:$A,"0"),数据!$B:$B,"")} -> TON活动赞助费 | J28: TONX | K28: {=_xlfn.XLOOKUP(TEXT(G28,"0"),TEXT(数据!$A:$A,"0"),数据!$D:$D,"")} -> 0x7d144265354d1d2600ecfeb277bb1cfaced9dc19
A29: 1 | B29: 45575 | C29: 26 | D29: Tencent Cloud Server 42991655 | E29: 5000 | F29: IT Costs | G29: 42991655 | H29: Research and development expenses - IT costs | I29: {=_xlfn.XLOOKUP(TEXT(G29,"0"),TEXT(数据!$A:$A,"0"),数据!$B:$B,"")} -> 腾讯云服务器 | J29: Tencent Cloud Server | K29: {=_xlfn.XLOOKUP(TEXT(G29,"0"),TEXT(数据!$A:$A,"0"),数据!$D:$D,"")} -> 0x1bcdc9450671e3895362d315a6174dd8442af9ab
A30: 2 | B30: 45617 | C30: 58 | D30: Tencent Cloud Top-up 276721226 | E30: 5000 | F30: IT Costs | G30: 276721226 | H30: Research and development expenses - IT costs | I30: {=_xlfn.XLOOKUP(TEXT(G30,"0"),TEXT(数据!$A:$A,"0"),数据!$B:$B,"")} -> 腾讯云充值 | J30: Tencent Cloud | K30: {=_xlfn.XLOOKUP(TEXT(G30,"0"),TEXT(数据!$A:$A,"0"),数据!$D:$D,"")} -> 0x54b755175f28486ee68208e081ff6561bcf3a864
A31: 3 | B31: 45677 | C31: 69 | D31: Server Fees 21665383 | E31: 5504 | F31: IT Costs | G31: 21665383 | H31: Research and development expenses - IT costs | I31: {=_xlfn.XLOOKUP(TEXT(G31,"0"),TEXT(数据!$A:$A,"0"),数据!$B:$B,"")} -> Aptos 节点过去两个月服务器费用 $5504 | J31: Tencent Cloud | K31: {=_xlfn.XLOOKUP(TEXT(G31,"0"),TEXT(数据!$A:$A,"0"),数据!$D:$D,"")} -> 0x54B755175F28486ee68208E081Ff6561bCF3A864
A32: 4 | B32: 45726 | C32: 29 | D32: Tencent Cloud Top-up 314211921 | E32: 5000 | F32: IT Costs | G32: 314211921 | H32: Research and development expenses - IT costs | I32: {=_xlfn.XLOOKUP(TEXT(G32,"0"),TEXT(数据!$A:$A,"0"),数据!$B:$B,"")} -> 腾讯云充值 | J32: Tencent Cloud | K32: {=_xlfn.XLOOKUP(TEXT(G32,"0"),TEXT(数据!$A:$A,"0"),数据!$D:$D,"")} -> 0x54b755175f28486ee68208e081ff6561bcf3a864
A33: 5 | B33: 45776 | C33: 67 | D33: Tencent Cloud Servers48784872 | E33: 5000 | F33: IT Costs | G33: 48784872 | H33: Research and development expenses - IT costs | I33: {=_xlfn.XLOOKUP(TEXT(G33,"0"),TEXT(数据!$A:$A,"0"),数据!$B:$B,"")} -> 腾讯云服务器 | J33: Tencent Cloud | K33: {=_xlfn.XLOOKUP(TEXT(G33,"0"),TEXT(数据!$A:$A,"0"),数据!$D:$D,"")} -> 0x54b755175f28486ee68208e081ff6561bcf3a864
A34: 6 | B34: 45878 | C34: 24 | D34: Tencent Cloud TCI372862447 | E34: 5000 | F34: IT Costs | G34: 372862447 | H34: Research and development expenses - IT costs | I34: {=_xlfn.XLOOKUP(TEXT(G34,"0"),TEXT(数据!$A:$A,"0"),数据!$B:$B,"")} -> 腾讯云TCI | J34: Tencent Cloud | K34: {=_xlfn.XLOOKUP(TEXT(G34,"0"),TEXT(数据!$A:$A,"0"),数据!$D:$D,"")} -> 0x54B755175F28486ee68208E081Ff6561bCF3A864
A35: 7 | B35: 45929 | C35: 113 | D35: 62874650 | E35: 15000 | F35: IT Costs | G35: 62874650 | H35: Research and development expenses - IT costs | I35: {=_xlfn.XLOOKUP(TEXT(G35,"0"),TEXT(数据!$A:$A,"0"),数据!$B:$B,"")} -> 购买Kekkai 插件产品 | J35: Kekkai | K35: {=_xlfn.XLOOKUP(TEXT(G35,"0"),TEXT(数据!$A:$A,"0"),数据!$D:$D,"")} -> 0xc48eB35DBe9e96067D71308E17133ca358160267
A36: 1 | B36: 45525 | C36: 56 | D36: Tencent Cloud top-up 41544927 | E36: 5000 | F36: IT Costs | G36: 41544927 | H36: Research and development expenses - IT costs | I36: {=_xlfn.XLOOKUP(TEXT(G36,"0"),TEXT(数据!$A:$A,"0"),数据!$B:$B,"")} -> 充值腾讯云 | J36: Tencent Cloud | K36: {=_xlfn.XLOOKUP(TEXT(G36,"0"),TEXT(数据!$A:$A,"0"),数据!$D:$D,"")} -> 0xdc9c27203edf644cac8f0e53fab810977f7a3361
A37: 2 | B37: 45525 | C37: 57 | D37: Cloud top-up 41544918 | E37: 1817 | F37: IT Costs | G37: 41544918 | H37: Research and development expenses - IT costs | I37: {=_xlfn.XLOOKUP(TEXT(G37,"0"),TEXT(数据!$A:$A,"0"),数据!$B:$B,"")} -> 云充值 | J37: Web3hub | K37: {=_xlfn.XLOOKUP(TEXT(G37,"0"),TEXT(数据!$A:$A,"0"),数据!$D:$D,"")} -> 0xdc9c27203edf644cac8f0e53fab810977f7a3361
A38: 1 | B38: 45680 | C38: 87 | D38: AC payment refund 21685792 | E38: 30000 | F38: Other Payables - Individuals | G38: 21685792 | H38: Dissemination expenses | I38: {=_xlfn.XLOOKUP(TEXT(G38,"0"),TEXT(数据!$A:$A,"0"),数据!$B:$B,"")} -> AC Capital打款返还 | J38: AC Capital (Cayman) | K38: {=_xlfn.XLOOKUP(TEXT(G38,"0"),TEXT(数据!$A:$A,"0"),数据!$D:$D,"")} -> 0x377374d7cd5041e058d7bd584a15cc3a62cbbd4b
A39: 2 | B39: 45742 | C39: 73 | D39: Sancus Venture 22128255 | E39: 100000 | F39: Other Payables - Individuals | G39: 22128255 | H39: Dissemination expenses | I39: {=_xlfn.XLOOKUP(TEXT(G39,"0"),TEXT(数据!$A:$A,"0"),数据!$B:$B,"")} -> 回购10万美元股份 | J39: Sancus Venture | K39: {=_xlfn.XLOOKUP(TEXT(G39,"0"),TEXT(数据!$A:$A,"0"),数据!$D:$D,"")} -> 0xd135f860ce5deffc7ca0eb09c3cce00f045d4f58

Sheet 数据
A1: Blockno | B1: Project Name | C1: Payer Name | D1: To
A2: 18489905 | B2: 新加坡公司注册费用 | C2: AVAILABIZ PTE LTD | D2: 0x6bde7a4bc4cfc75429f65b90227496d3cad6424c
A3: 18316604 | B3: MSafe | C3: Rize labs Inc | D3: 0x0bc2bf02aabf89d1556c4134784ab7535c442b68
A4: 20839248 | B4: Movement Event Part 2 | C4: MVMT LABS INC. | D4: 0x0bc2bf02aabf89d1556c4134784ab7535c442b68
A5: 20834095 | B5: StreamFlow | C5: STREAMFLOW CYPRUS LTD | D5: 0x0bc2bf02aabf89d1556c4134784ab7535c442b68
A6: 20794043 | B6: SNX | C6: WEB3 LABS LTD | D6: 0x0bc2bf02aabf89d1556c4134784ab7535c442b68
A7: 20739031 | B7: Nirvana | C7: ELECTRIC NIRVANA LLC | D7: 0x0bc2bf02aabf89d1556c4134784ab7535c442b68
A8: 20738966 | B8: Nirvana | C8: ELECTRIC NIRVANA LLC | D8: 0x0bc2bf02aabf89d1556c4134784ab7535c442b68
A9: 20721068 | B9: SNX | C9: WEB3 LABS LTD | D9: 0x0bc2bf02aabf89d1556c4134784ab7535c442b68
A10: 20718756 | B10: Ambrus | C10: AMBRUS LTD | D10: 0x0bc2bf02aabf89d1556c4134784ab7535c442b68
A11: 20716195 | B11: Pharos 活动费用尾款 | C11: PHAROS AI, INC. | D11: 0x0bc2bf02aabf89d1556c4134784ab7535c442b68
A12: 20693925 | B12: Ambrus | C12: AMBRUS LTD | D12: 0x0bc2bf02aabf89d1556c4134784ab7535c442b68
A13: 20676278 | B13: 产品技术合作 | C13: NFTSCAN TECHNOLOGY PTE.LTD | D13: 0x1bcdc9450671e3895362d315a6174dd8442af9ab
... A1063: 62874650 | B1063: 购买Kekkai 插件产品 | C1063: Kekkai | D1063: 0xc48eB35DBe9e96067D71308E17133ca358160267

Sheet 需提供凭证
A1: 截止测试-收入
A2: No. | B2: Name of customer | C2: Voucher date | D2: Voucher number | H2: Invoice number | I2: Invoice date
E4: Confirmation Letter amount | F4: Confirmation Letter Date
A5: 2 | B5: XMONEY PTY LTD | C5: 20250907 | D5: 49
A6: 3 | B6: XMONEY PTY LTD | C6: 20250915 | D6: 60
A7: 12 | B7: WEB3 LABS LTD | C7: 20240911 | D7: 40
A8: 20 | B8: WEB3 LABS LTD | C8: 20240920 | D8: 75
A9: 4 | B9: WEB3 ENGINEERING LTD | C9: 20250915 | D9: 59
A10: 17 | B10: UNTITLED CORPORATION PROJECT INC. | C10: 20240916 | D10: 68
A11: 13 | B11: TRADERS.TECH LIMITED | C11: 20240912 | D11: 43
A12: 18 | B12: The Payment Solution Limited | C12: 20240918 | D12: 71
A13: 27 | B13: STREAMFLOW CYPRUS LTD | C13: 20240926 | D13: 92
A14: 10 | B14: Soda Ventures LTD | C14: 20250927 | D14: 85
A15: 1 | B15: Router Works, Inc. | C15: 20240902 | D15: 2
A16: 23 | B16: Router Works, Inc. | C16: 20240924 | D16: 81
... A54: 4 | B54: 404 BLOCKCHAIN LLC | C54: 20240904 | D54: 9
A55: 1 | B55: TROPIC SEASCAPE PTE. LTD | C55: 20251015 | D55: 37
A56: 2 | B56: Mercury Protocol PTE. LTD | C56: 20251001 | D56: 26
A57: 3 | B57: Orion Limited | C57: 20251014 | D57: 69
A58: 4 | B58: RARESHOP LIMITED | C58: 20251008 | D58: 43
A59: 5 | B59: Superchillclub Limited | C59: 20251025 | D59: 44
A60: 6 | B60: Rivera Money Inc | C60: 20251017 | D60: 34
A61: 7 | B61: RARESHOP LIMITED | C61: 20251010 | D61: 32
A62: 8 | B62: Echo International Group Corp | C62: 20251016 | D62: 23
A63: 9 | B63: Gumi Inc | C63: 20251021 | D63: 24
A64: 10 | B64: Rize labs Inc | C64: 20251014 | D64: 35
A65: 11 | B65: DEB CORP | C65: 20251009 | D65: 22
A66: 12 | B66: Oben Club GmbH | C66: 20251023 | D66: 20
... A69: 15 | B69: Kenentoshi Co., Ltd | C69: 20251014 | D69: 67
A73: No | B73: Date | C73: Voucher number | D73: Abstract | E73: USD | F73: Account Name | G73: Abstract | H73: Project Name | I73: Payer Name | J73: To
A74: 1 | B74: 2024-12-05 | C74: 10 | D74: 21335372 | E74: 1850 | F74: Promotion expenses | G74: 21335372
A75: 2 | B75: 2024-12-10 | C75: 30 | D75: 44724294 | E75: 2940 | F75: Promotion expenses | G75: 44724294
A76: 4 | B76: 2024-12-10 | C76: 32 | D76: 44724274 | E76: 2200 | F76: Promotion expenses | G76: 44724274
A77: 6 | B77: 2024-12-10 | C77: 36 | D77: 44724252 | E77: 19600 | F77: Promotion expenses | G77: 44724252
A78: 7 | B78: 2024-12-25 | C78: 78 | D78: 21477477 | E78: 1450 | F78: Promotion expenses | G78: 21477477
A79: 13 | B79: 2025-01-05 | C79: 15 | D79: 292124417 | E79: 2160 | F79: Promotion expenses | G79: 292124417
A80: 18 | B80: 2025-04-25 | C80: 59 | D80: 22339398 | E80: 2200 | F80: Promotion expenses | G80: 22339398
A81: 21 | B81: 2025-05-18 | C81: 46 | D81: 22507240 | E81: 1650 | F81: Promotion expenses | G81: 22507240
A82: 22 | B82: 2025-08-06 | C82: 11 | D82: 23078858 | E82: 1500 | F82: Promotion expenses | G82: 23078858
A83: 23 | B83: 2025-08-06 | C83: 12 | D83: 23078846 | E83: 2295 | F83: Promotion expenses | G83: 23078846
...

Sheet 费用等相关
A1: 细节抽样
A2: No | B2: Date | C2: Voucher number | D2: Abstract | E2: USD | F2: Account Name
A3: 1 | B3: 2024-12-05 | C3: 10 | D3: 21335372 | E3: 1850 | F3: Promotion expenses
A4: 2 | B4: 2024-12-10 | C4: 30 | D4: 44724294 | E4: 2940 | F4: Promotion expenses
A5: 4 | B5: 2024-12-10 | C5: 32 | D5: 44724274 | E5: 2200 | F5: Promotion expenses
A6: 6 | B6: 2024-12-10 | C6: 36 | D6: 44724252 | E6: 19600 | F6: Promotion expenses
A7: 7 | B7: 2024-12-25 | C7: 78 | D7: 21477477 | E7: 1450 | F7: Promotion expenses
A8: 13 | B8: 2025-01-05 | C8: 15 | D8: 292124417 | E8: 2160 | F8: Promotion expenses
A9: 18 | B9: 2025-04-25 | C9: 59 | D9: 22339398 | E9: 2200 | F9: Promotion expenses
A10: 21 | B10: 2025-05-18 | C10: 46 | D10: 22507240 | E10: 1650 | F10: Promotion expenses
A11: 22 | B11: 2025-08-06 | C11: 11 | D11: 23078858 | E11: 1500 | F11: Promotion expenses
A12: 23 | B12: 2025-08-06 | C12: 12 | D12: 23078846 | E12: 2295 | F12: Promotion expenses
A13: 24 | B13: 2025-09-04 | C13: 25 | D13: 59983249 | E13: 2817 | F13: Promotion expenses
A14: 25 | B14: 2025-09-18 | C14: 66 | D14: 61567559 | E14: 1716 | F14: Promotion expenses
A15: 26 | B15: 2025-09-18 | C15: 67 | D15: 61567809 | E15: 5000 | F15: Promotion expenses
A16: 27 | B16: 2025-09-18 | C16: 68 | D16: 61567930 | E16: 4000 | F16: Promotion expenses
A17: 28 | B17: 2024-11-12 | C17: 59 | D17: 21165630 | E17: 9500 | F17: Audit fee
A18: 29 | B18: 2025-04-08 | C18: 19 | D18: 323891119 | E18: 2000 | F18: Audit fee
A19: 30 | B19: 2024-10-25 | C19: 71 | D19: 43417628 | E19: 12780 | F19: Other event expenses
A20: 31 | B20: 2024-11-04 | C20: 66 | D20: 21113385 | E20: 10000 | F20: Other event expenses
A21: 32 | B21: 2025-02-15 | C21: 62 | D21: 21845084 | E21: 22883 | F21: Other event expenses
A22: 33 | B22: 2025-03-07 | C22: 16 | D22: 21993365 | E22: -7295 | F22: Other event expenses
A23: 38 | B23: 2024-02-09 | C23: 35 | D23: 35970263 | E23: 5000 | F23: Brand promotion expenses
A24: 40 | B24: 2024-08-29 | C24: 71 | D24: 20632877 | E24: 10000 | F24: Brand promotion expenses
A25: 41 | B25: 2024-09-02 | C25: 3 | D25: 249149323 | E25: 2502 | F25: Brand promotion expenses
A26: 42 | B26: 2023-11-03 | C26: 1 | D26: 18489905 | E26: 5225 | F26: Office expenses
A27: 43 | B27: 2024-04-16 | C27: 48 | D27: 19660796 | E27: 8470 | F27: Office expenses
A28: 44 | B28: 2024-02-26 | C28: 61 | D28: 19310019 | E28: 1398.91 | F28: Exhibition expenses
A29: 46 | B29: 2024-04-30 | C29: 109 | D29: 206346955 | E29: 5435 | F29: Exhibition expenses
A30: 细节抽样
A31: No | B31: Date | C31: Voucher number | D31: Abstract | E31: USD | F31: Account Name
A32: 1 | B32: 45575 | C32: 26 | D32: Tencent Cloud Server 42991655 | E32: 5000 | F32: IT Costs
A33: 2 | B33: 45617 | C33: 58 | D33: Tencent Cloud Top-up 276721226 | E33: 5000 | F33: IT Costs
A34: 3 | B34: 45677 | C34: 69 | D34: Server Fees 21665383 | E34: 5504 | F34: IT Costs
A35: 4 | B35: 45726 | C35: 29 | D35: Tencent Cloud Top-up 314211921 | E35: 5000 | F35: IT Costs
A36: 5 | B36: 45776 | C36: 67 | D36: Tencent Cloud Servers48784872 | E36: 5000 | F36: IT Costs
A37: 6 | B37: 45878 | C37: 24 | D37: Tencent Cloud TCI372862447 | E37: 5000 | F37: IT Costs
A38: 7 | B38: 45929 | C38: 113 | D38: 62874650 | E38: 15000 | F38: IT Costs
A39: 细节抽样
A40: No | B40: Date | C40: Voucher number | D40: Abstract | E40: USD | F40: Account Name
...
